Workbook

Sheet Instructions
A1: How to Use This Tracker
A4: 1. Settings — set your program Start Date (must be a Monday), baseline weight/waist, and goals. Everything else recalculates from this.
A5: 2. Strength Log — after each Mon/Wed/Fri session, fill in Sets Completed, Reps Completed, and Weight Used (lb) for each exercise.
A6: 3. Daily Log — after each jog, fill in Jog Distance (mi) and Jog Duration (min). Pace and strength completion are calculated automatically.
A7: 4. Weight & Waist — every weekend (Sunday), fill in that week's Weight (lb) and Waist (in). Week 0 is your baseline and is pre-filled.
A8: 5. Trends & Dashboard — these update automatically. Just open the Dashboard tab to see your progress charts.
A10: Blue text = cells you type into. Green text = formulas linking to another sheet. Black text = calculated formulas.
A11: If a chart looks empty, it's because there's no logged data yet for that week — it will populate as you fill in the log sheets.

Sheet Settings
A1: Program Settings
A2: Edit these values — everything else in the workbook updates automatically.
A4: Start Date (must be a Monday) | B4: 46209
A5: Baseline Weight (lb) | B5: 185
A6: Baseline Waist (in) | B6: 35
A7: Goal Weight (lb) | B7: 165
A8: Goal Waist (in) | B8: 32
A9: Baseline Monthly Mileage (mi) | B9: 60
A10: Target Strength Sessions / Week | B10: 3
A11: Program Length (weeks) | B11: 12

Sheet Plan Reference
A1: Exercise Plan Reference
A2: Source: INPUTS/amits_weekly_workout.md — used by Strength Log to look up target sets/reps.
A4: Workout Day | B4: Exercise | C4: Target Sets | D4: Target Reps
A5: Circuit A - Lower Body & Core (Monday) | B5: Goblet Squat | C5: 3 | D5: 12
A6: Circuit A - Lower Body & Core (Monday) | B6: Dumbbell Romanian Deadlift | C6: 3 | D6: 12
A7: Circuit A - Lower Body & Core (Monday) | B7: Dumbbell Walking Lunge | C7: 3 | D7: 10/leg
A8: Circuit A - Lower Body & Core (Monday) | B8: Glute Bridge | C8: 3 | D8: 15
A9: Circuit A - Lower Body & Core (Monday) | B9: Plank | C9: 3 | D9: 30-45 sec
A10: Circuit A - Lower Body & Core (Monday) | B10: Standing Calf Raise | C10: 3 | D10: 15
A11: Circuit B - Upper Body & Core (Wednesday) | B11: Dumbbell Floor Press | C11: 3 | D11: 12
A12: Circuit B - Upper Body & Core (Wednesday) | B12: Dumbbell Bent-Over Row | C12: 3 | D12: 12
A13: Circuit B - Upper Body & Core (Wednesday) | B13: Dumbbell Shoulder Press | C13: 3 | D13: 12
A14: Circuit B - Upper Body & Core (Wednesday) | B14: Band Pull-Apart | C14: 3 | D14: 15
A15: Circuit B - Upper Body & Core (Wednesday) | B15: Dumbbell Bicep Curl | C15: 3 | D15: 12
A16: Circuit B - Upper Body & Core (Wednesday) | B16: Dead Bug | C16: 3 | D16: 12/side
... A22: Circuit C - Full Body & Core (Friday) | B22: Mountain Climbers | C22: 3 | D22: 30 sec

Sheet Daily Log
A1: Daily Log
A2: One row per calendar day. Fill in Jog Distance/Duration on jog days; strength completion pulls automatically from Strength Log.
A4: Week # | B4: Date | C4: Day | D4: Planned Activity | E4: Jog Distance (mi) | F4: Jog Duration (min) | G4: Jog Pace (min/mi) | H4: Strength Exercises Logged | I4: Notes
A5: 1 | B5: =Settings!$B$4+(A5-1)*7+0 -> 46209 | C5: =TEXT(B5,"dddd") -> Monday | D5: Jog 3-4 mi + Circuit A | G5: =IFERROR(F5/E5,"") | H5: =COUNTIFS('Strength Log'!$B$5:$B$220,B5,'Strength Log'!$H$5:$H$220,"<>") -> 0
A6: 1 | B6: =Settings!$B$4+(A6-1)*7+1 -> 46210 | C6: =TEXT(B6,"dddd") -> Tuesday | D6: Mobility & Stretch | G6: =IFERROR(F6/E6,"") | H6: =COUNTIFS('Strength Log'!$B$5:$B$220,B6,'Strength Log'!$H$5:$H$220,"<>") -> 0
A7: 1 | B7: =Settings!$B$4+(A7-1)*7+2 -> 46211 | C7: =TEXT(B7,"dddd") -> Wednesday | D7: Jog 3-4 mi + Circuit B | G7: =IFERROR(F7/E7,"") | H7: =COUNTIFS('Strength Log'!$B$5:$B$220,B7,'Strength Log'!$H$5:$H$220,"<>") -> 0
A8: 1 | B8: =Settings!$B$4+(A8-1)*7+3 -> 46212 | C8: =TEXT(B8,"dddd") -> Thursday | D8: Optional walk / Rest | G8: =IFERROR(F8/E8,"") | H8: =COUNTIFS('Strength Log'!$B$5:$B$220,B8,'Strength Log'!$H$5:$H$220,"<>") -> 0
A9: 1 | B9: =Settings!$B$4+(A9-1)*7+4 -> 46213 | C9: =TEXT(B9,"dddd") -> Friday | D9: Jog 3-4 mi + Circuit C | G9: =IFERROR(F9/E9,"") | H9: =COUNTIFS('Strength Log'!$B$5:$B$220,B9,'Strength Log'!$H$5:$H$220,"<>") -> 0
A10: 1 | B10: =Settings!$B$4+(A10-1)*7+5 -> 46214 | C10: =TEXT(B10,"dddd") -> Saturday | D10: Long Jog ~4 mi | G10: =IFERROR(F10/E10,"") | H10: =COUNTIFS('Strength Log'!$B$5:$B$220,B10,'Strength Log'!$H$5:$H$220,"<>") -> 0
A11: 1 | B11: =Settings!$B$4+(A11-1)*7+6 -> 46215 | C11: =TEXT(B11,"dddd") -> Sunday | D11: Rest Day | G11: =IFERROR(F11/E11,"") | H11: =COUNTIFS('Strength Log'!$B$5:$B$220,B11,'Strength Log'!$H$5:$H$220,"<>") -> 0
A12: 2 | B12: =Settings!$B$4+(A12-1)*7+0 -> 46216 | C12: =TEXT(B12,"dddd") -> Monday | D12: Jog 3-4 mi + Circuit A | G12: =IFERROR(F12/E12,"") | H12: =COUNTIFS('Strength Log'!$B$5:$B$220,B12,'Strength Log'!$H$5:$H$220,"<>") -> 0
A13: 2 | B13: =Settings!$B$4+(A13-1)*7+1 -> 46217 | C13: =TEXT(B13,"dddd") -> Tuesday | D13: Mobility & Stretch | G13: =IFERROR(F13/E13,"") | H13: =COUNTIFS('Strength Log'!$B$5:$B$220,B13,'Strength Log'!$H$5:$H$220,"<>") -> 0
A14: 2 | B14: =Settings!$B$4+(A14-1)*7+2 -> 46218 | C14: =TEXT(B14,"dddd") -> Wednesday | D14: Jog 3-4 mi + Circuit B | G14: =IFERROR(F14/E14,"") | H14: =COUNTIFS('Strength Log'!$B$5:$B$220,B14,'Strength Log'!$H$5:$H$220,"<>") -> 0
A15: 2 | B15: =Settings!$B$4+(A15-1)*7+3 -> 46219 | C15: =TEXT(B15,"dddd") -> Thursday | D15: Optional walk / Rest | G15: =IFERROR(F15/E15,"") | H15: =COUNTIFS('Strength Log'!$B$5:$B$220,B15,'Strength Log'!$H$5:$H$220,"<>") -> 0
A16: 2 | B16: =Settings!$B$4+(A16-1)*7+4 -> 46220 | C16: =TEXT(B16,"dddd") -> Friday | D16: Jog 3-4 mi + Circuit C | G16: =IFERROR(F16/E16,"") | H16: =COUNTIFS('Strength Log'!$B$5:$B$220,B16,'Strength Log'!$H$5:$H$220,"<>") -> 0
A17: 2 | B17: =Settings!$B$4+(A17-1)*7+5 -> 46221 | C17: =TEXT(B17,"dddd") -> Saturday | D17: Long Jog ~4 mi | G17: =IFERROR(F17/E17,"") | H17: =COUNTIFS('Strength Log'!$B$5:$B$220,B17,'Strength Log'!$H$5:$H$220,"<>") -> 0
A18: 2 | B18: =Settings!$B$4+(A18-1)*7+6 -> 46222 | C18: =TEXT(B18,"dddd") -> Sunday | D18: Rest Day | G18: =IFERROR(F18/E18,"") | H18: =COUNTIFS('Strength Log'!$B$5:$B$220,B18,'Strength Log'!$H$5:$H$220,"<>") -> 0
A19: 3 | B19: =Settings!$B$4+(A19-1)*7+0 -> 46223 | C19: =TEXT(B19,"dddd") -> Monday | D19: Jog 3-4 mi + Circuit A | G19: =IFERROR(F19/E19,"") | H19: =COUNTIFS('Strength Log'!$B$5:$B$220,B19,'Strength Log'!$H$5:$H$220,"<>") -> 0
A20: 3 | B20: =Settings!$B$4+(A20-1)*7+1 -> 46224 | C20: =TEXT(B20,"dddd") -> Tuesday | D20: Mobility & Stretch | G20: =IFERROR(F20/E20,"") | H20: =COUNTIFS('Strength Log'!$B$5:$B$220,B20,'Strength Log'!$H$5:$H$220,"<>") -> 0
A21: 3 | B21: =Settings!$B$4+(A21-1)*7+2 -> 46225 | C21: =TEXT(B21,"dddd") -> Wednesday | D21: Jog 3-4 mi + Circuit B | G21: =IFERROR(F21/E21,"") | H21: =COUNTIFS('Strength Log'!$B$5:$B$220,B21,'Strength Log'!$H$5:$H$220,"<>") -> 0
A22: 3 | B22: =Settings!$B$4+(A22-1)*7+3 -> 46226 | C22: =TEXT(B22,"dddd") -> Thursday | D22: Optional walk / Rest | G22: =IFERROR(F22/E22,"") | H22: =COUNTIFS('Strength Log'!$B$5:$B$220,B22,'Strength Log'!$H$5:$H$220,"<>") -> 0
A23: 3 | B23: =Settings!$B$4+(A23-1)*7+4 -> 46227 | C23: =TEXT(B23,"dddd") -> Friday | D23: Jog 3-4 mi + Circuit C | G23: =IFERROR(F23/E23,"") | H23: =COUNTIFS('Strength Log'!$B$5:$B$220,B23,'Strength Log'!$H$5:$H$220,"<>") -> 0
A24: 3 | B24: =Settings!$B$4+(A24-1)*7+5 -> 46228 | C24: =TEXT(B24,"dddd") -> Saturday | D24: Long Jog ~4 mi | G24: =IFERROR(F24/E24,"") | H24: =COUNTIFS('Strength Log'!$B$5:$B$220,B24,'Strength Log'!$H$5:$H$220,"<>") -> 0
A25: 3 | B25: =Settings!$B$4+(A25-1)*7+6 -> 46229 | C25: =TEXT(B25,"dddd") -> Sunday | D25: Rest Day | G25: =IFERROR(F25/E25,"") | H25: =COUNTIFS('Strength Log'!$B$5:$B$220,B25,'Strength Log'!$H$5:$H$220,"<>") -> 0
A26: 4 | B26: =Settings!$B$4+(A26-1)*7+0 -> 46230 | C26: =TEXT(B26,"dddd") -> Monday | D26: Jog 3-4 mi + Circuit A | G26: =IFERROR(F26/E26,"") | H26: =COUNTIFS('Strength Log'!$B$5:$B$220,B26,'Strength Log'!$H$5:$H$220,"<>") -> 0
A27: 4 | B27: =Settings!$B$4+(A27-1)*7+1 -> 46231 | C27: =TEXT(B27,"dddd") -> Tuesday | D27: Mobility & Stretch | G27: =IFERROR(F27/E27,"") | H27: =COUNTIFS('Strength Log'!$B$5:$B$220,B27,'Strength Log'!$H$5:$H$220,"<>") -> 0
A28: 4 | B28: =Settings!$B$4+(A28-1)*7+2 -> 46232 | C28: =TEXT(B28,"dddd") -> Wednesday | D28: Jog 3-4 mi + Circuit B | G28: =IFERROR(F28/E28,"") | H28: =COUNTIFS('Strength Log'!$B$5:$B$220,B28,'Strength Log'!$H$5:$H$220,"<>") -> 0
A29: 4 | B29: =Settings!$B$4+(A29-1)*7+3 -> 46233 | C29: =TEXT(B29,"dddd") -> Thursday | D29: Optional walk / Rest | G29: =IFERROR(F29/E29,"") | H29: =COUNTIFS('Strength Log'!$B$5:$B$220,B29,'Strength Log'!$H$5:$H$220,"<>") -> 0
A30: 4 | B30: =Settings!$B$4+(A30-1)*7+4 -> 46234 | C30: =TEXT(B30,"dddd") -> Friday | D30: Jog 3-4 mi + Circuit C | G30: =IFERROR(F30/E30,"") | H30: =COUNTIFS('Strength Log'!$B$5:$B$220,B30,'Strength Log'!$H$5:$H$220,"<>") -> 0
A31: 4 | B31: =Settings!$B$4+(A31-1)*7+5 -> 46235 | C31: =TEXT(B31,"dddd") -> Saturday | D31: Long Jog ~4 mi | G31: =IFERROR(F31/E31,"") | H31: =COUNTIFS('Strength Log'!$B$5:$B$220,B31,'Strength Log'!$H$5:$H$220,"<>") -> 0
A32: 4 | B32: =Settings!$B$4+(A32-1)*7+6 -> 46236 | C32: =TEXT(B32,"dddd") -> Sunday | D32: Rest Day | G32: =IFERROR(F32/E32,"") | H32: =COUNTIFS('Strength Log'!$B$5:$B$220,B32,'Strength Log'!$H$5:$H$220,"<>") -> 0
A33: 5 | B33: =Settings!$B$4+(A33-1)*7+0 -> 46237 | C33: =TEXT(B33,"dddd") -> Monday | D33: Jog 3-4 mi + Circuit A | G33: =IFERROR(F33/E33,"") | H33: =COUNTIFS('Strength Log'!$B$5:$B$220,B33,'Strength Log'!$H$5:$H$220,"<>") -> 0
A34: 5 | B34: =Settings!$B$4+(A34-1)*7+1 -> 46238 | C34: =TEXT(B34,"dddd") -> Tuesday | D34: Mobility & Stretch | G34: =IFERROR(F34/E34,"") | H34: =COUNTIFS('Strength Log'!$B$5:$B$220,B34,'Strength Log'!$H$5:$H$220,"<>") -> 0
A35: 5 | B35: =Settings!$B$4+(A35-1)*7+2 -> 46239 | C35: =TEXT(B35,"dddd") -> Wednesday | D35: Jog 3-4 mi + Circuit B | G35: =IFERROR(F35/E35,"") | H35: =COUNTIFS('Strength Log'!$B$5:$B$220,B35,'Strength Log'!$H$5:$H$220,"<>") -> 0
A36: 5 | B36: =Settings!$B$4+(A36-1)*7+3 -> 46240 | C36: =TEXT(B36,"dddd") -> Thursday | D36: Optional walk / Rest | G36: =IFERROR(F36/E36,"") | H36: =COUNTIFS('Strength Log'!$B$5:$B$220,B36,'Strength Log'!$H$5:$H$220,"<>") -> 0
A37: 5 | B37: =Settings!$B$4+(A37-1)*7+4 -> 46241 | C37: =TEXT(B37,"dddd") -> Friday | D37: Jog 3-4 mi + Circuit C | G37: =IFERROR(F37/E37,"") | H37: =COUNTIFS('Strength Log'!$B$5:$B$220,B37,'Strength Log'!$H$5:$H$220,"<>") -> 0
A38: 5 | B38: =Settings!$B$4+(A38-1)*7+5 -> 46242 | C38: =TEXT(B38,"dddd") -> Saturday | D38: Long Jog ~4 mi | G38: =IFERROR(F38/E38,"") | H38: =COUNTIFS('Strength Log'!$B$5:$B$220,B38,'Strength Log'!$H$5:$H$220,"<>") -> 0
A39: 5 | B39: =Settings!$B$4+(A39-1)*7+6 -> 46243 | C39: =TEXT(B39,"dddd") -> Sunday | D39: Rest Day | G39: =IFERROR(F39/E39,"") | H39: =COUNTIFS('Strength Log'!$B$5:$B$220,B39,'Strength Log'!$H$5:$H$220,"<>") -> 0
A40: 6 | B40: =Settings!$B$4+(A40-1)*7+0 -> 46244 | C40: =TEXT(B40,"dddd") -> Monday | D40: Jog 3-4 mi + Circuit A | G40: =IFERROR(F40/E40,"") | H40: =COUNTIFS('Strength Log'!$B$5:$B$220,B40,'Strength Log'!$H$5:$H$220,"<>") -> 0
A41: 6 | B41: =Settings!$B$4+(A41-1)*7+1 -> 46245 | C41: =TEXT(B41,"dddd") -> Tuesday | D41: Mobility & Stretch | G41: =IFERROR(F41/E41,"") | H41: =COUNTIFS('Strength Log'!$B$5:$B$220,B41,'Strength Log'!$H$5:$H$220,"<>") -> 0
...

Sheet Strength Log
A1: Strength Log
A2: Fill in Sets/Reps Completed and Weight Used after each strength session. This is the source data for exercise trend charts.
A4: Week # | B4: Date | C4: Day | D4: Workout Day | E4: Exercise | F4: Target Sets | G4: Target Reps | H4: Sets Completed | I4: Reps Completed | J4: Weight Used (lb) | K4: Notes
A5: 1 | B5: =Settings!$B$4+(A5-1)*7+0 -> 46209 | C5: =TEXT(B5,"dddd") -> Monday | D5: Circuit A - Lower Body & Core (Monday) | E5: Goblet Squat | F5: =INDEX('Plan Reference'!$C$5:$C$22,MATCH(E5,'Plan Reference'!$B$5:$B$22,0)) -> 3 | G5: =INDEX('Plan Reference'!$D$5:$D$22,MATCH(E5,'Plan Reference'!$B$5:$B$22,0)) -> 12
A6: 1 | B6: =Settings!$B$4+(A6-1)*7+0 -> 46209 | C6: =TEXT(B6,"dddd") -> Monday | D6: Circuit A - Lower Body & Core (Monday) | E6: Dumbbell Romanian Deadlift | F6: =INDEX('Plan Reference'!$C$5:$C$22,MATCH(E6,'Plan Reference'!$B$5:$B$22,0)) -> 3 | G6: =INDEX('Plan Reference'!$D$5:$D$22,MATCH(E6,'Plan Reference'!$B$5:$B$22,0)) -> 12
A7: 1 | B7: =Settings!$B$4+(A7-1)*7+0 -> 46209 | C7: =TEXT(B7,"dddd") -> Monday | D7: Circuit A - Lower Body & Core (Monday) | E7: Dumbbell Walking Lunge | F7: =INDEX('Plan Reference'!$C$5:$C$22,MATCH(E7,'Plan Reference'!$B$5:$B$22,0)) -> 3 | G7: =INDEX('Plan Reference'!$D$5:$D$22,MATCH(E7,'Plan Reference'!$B$5:$B$22,0)) -> 10/leg
A8: 1 | B8: =Settings!$B$4+(A8-1)*7+0 -> 46209 | C8: =TEXT(B8,"dddd") -> Monday | D8: Circuit A - Lower Body & Core (Monday) | E8: Glute Bridge | F8: =INDEX('Plan Reference'!$C$5:$C$22,MATCH(E8,'Plan Reference'!$B$5:$B$22,0)) -> 3 | G8: =INDEX('Plan Reference'!$D$5:$D$22,MATCH(E8,'Plan Reference'!$B$5:$B$22,0)) -> 15
A9: 1 | B9: =Settings!$B$4+(A9-1)*7+0 -> 46209 | C9: =TEXT(B9,"dddd") -> Monday | D9: Circuit A - Lower Body & Core (Monday) | E9: Plank | F9: =INDEX('Plan Reference'!$C$5:$C$22,MATCH(E9,'Plan Reference'!$B$5:$B$22,0)) -> 3 | G9: =INDEX('Plan Reference'!$D$5:$D$22,MATCH(E9,'Plan Reference'!$B$5:$B$22,0)) -> 30-45 sec
A10: 1 | B10: =Settings!$B$4+(A10-1)*7+0 -> 46209 | C10: =TEXT(B10,"dddd") -> Monday | D10: Circuit A - Lower Body & Core (Monday) | E10: Standing Calf Raise | F10: =INDEX('Plan Reference'!$C$5:$C$22,MATCH(E10,'Plan Reference'!$B$5:$B$22,0)) -> 3 | G10: =INDEX('Plan Reference'!$D$5:$D$22,MATCH(E10,'Plan Reference'!$B$5:$B$22,0)) -> 15
A11: 1 | B11: =Settings!$B$4+(A11-1)*7+2 -> 46211 | C11: =TEXT(B11,"dddd") -> Wednesday | D11: Circuit B - Upper Body & Core (Wednesday) | E11: Dumbbell Floor Press | F11: =INDEX('Plan Reference'!$C$5:$C$22,MATCH(E11,'Plan Reference'!$B$5:$B$22,0)) -> 3 | G11: =INDEX('Plan Reference'!$D$5:$D$22,MATCH(E11,'Plan Reference'!$B$5:$B$22,0)) -> 12
A12: 1 | B12: =Settings!$B$4+(A12-1)*7+2 -> 46211 | C12: =TEXT(B12,"dddd") -> Wednesday | D12: Circuit B - Upper Body & Core (Wednesday) | E12: Dumbbell Bent-Over Row | F12: =INDEX('Plan Reference'!$C$5:$C$22,MATCH(E12,'Plan Reference'!$B$5:$B$22,0)) -> 3 | G12: =INDEX('Plan Reference'!$D$5:$D$22,MATCH(E12,'Plan Reference'!$B$5:$B$22,0)) -> 12
A13: 1 | B13: =Settings!$B$4+(A13-1)*7+2 -> 46211 | C13: =TEXT(B13,"dddd") -> Wednesday | D13: Circuit B - Upper Body & Core (Wednesday) | E13: Dumbbell Shoulder Press | F13: =INDEX('Plan Reference'!$C$5:$C$22,MATCH(E13,'Plan Reference'!$B$5:$B$22,0)) -> 3 | G13: =INDEX('Plan Reference'!$D$5:$D$22,MATCH(E13,'Plan Reference'!$B$5:$B$22,0)) -> 12
A14: 1 | B14: =Settings!$B$4+(A14-1)*7+2 -> 46211 | C14: =TEXT(B14,"dddd") -> Wednesday | D14: Circuit B - Upper Body & Core (Wednesday) | E14: Band Pull-Apart | F14: =INDEX('Plan Reference'!$C$5:$C$22,MATCH(E14,'Plan Reference'!$B$5:$B$22,0)) -> 3 | G14: =INDEX('Plan Reference'!$D$5:$D$22,MATCH(E14,'Plan Reference'!$B$5:$B$22,0)) -> 15
A15: 1 | B15: =Settings!$B$4+(A15-1)*7+2 -> 46211 | C15: =TEXT(B15,"dddd") -> Wednesday | D15: Circuit B - Upper Body & Core (Wednesday) | E15: Dumbbell Bicep Curl | F15: =INDEX('Plan Reference'!$C$5:$C$22,MATCH(E15,'Plan Reference'!$B$5:$B$22,0)) -> 3 | G15: =INDEX('Plan Reference'!$D$5:$D$22,MATCH(E15,'Plan Reference'!$B$5:$B$22,0)) -> 12
A16: 1 | B16: =Settings!$B$4+(A16-1)*7+2 -> 46211 | C16: =TEXT(B16,"dddd") -> Wednesday | D16: Circuit B - Upper Body & Core (Wednesday) | E16: Dead Bug | F16: =INDEX('Plan Reference'!$C$5:$C$22,MATCH(E16,'Plan Reference'!$B$5:$B$22,0)) -> 3 | G16: =INDEX('Plan Reference'!$D$5:$D$22,MATCH(E16,'Plan Reference'!$B$5:$B$22,0)) -> 12/side
A17: 1 | B17: =Settings!$B$4+(A17-1)*7+4 -> 46213 | C17: =TEXT(B17,"dddd") -> Friday | D17: Circuit C - Full Body & Core (Friday) | E17: Dumbbell Thruster | F17: =INDEX('Plan Reference'!$C$5:$C$22,MATCH(E17,'Plan Reference'!$B$5:$B$22,0)) -> 3 | G17: =INDEX('Plan Reference'!$D$5:$D$22,MATCH(E17,'Plan Reference'!$B$5:$B$22,0)) -> 12
A18: 1 | B18: =Settings!$B$4+(A18-1)*7+4 -> 46213 | C18: =TEXT(B18,"dddd") -> Friday | D18: Circuit C - Full Body & Core (Friday) | E18: Renegade Row | F18: =INDEX('Plan Reference'!$C$5:$C$22,MATCH(E18,'Plan Reference'!$B$5:$B$22,0)) -> 3 | G18: =INDEX('Plan Reference'!$D$5:$D$22,MATCH(E18,'Plan Reference'!$B$5:$B$22,0)) -> 10/side
A19: 1 | B19: =Settings!$B$4+(A19-1)*7+4 -> 46213 | C19: =TEXT(B19,"dddd") -> Friday | D19: Circuit C - Full Body & Core (Friday) | E19: Reverse Lunge to Curl | F19: =INDEX('Plan Reference'!$C$5:$C$22,MATCH(E19,'Plan Reference'!$B$5:$B$22,0)) -> 3 | G19: =INDEX('Plan Reference'!$D$5:$D$22,MATCH(E19,'Plan Reference'!$B$5:$B$22,0)) -> 10/leg
A20: 1 | B20: =Settings!$B$4+(A20-1)*7+4 -> 46213 | C20: =TEXT(B20,"dddd") -> Friday | D20: Circuit C - Full Body & Core (Friday) | E20: Bird Dog | F20: =INDEX('Plan Reference'!$C$5:$C$22,MATCH(E20,'Plan Reference'!$B$5:$B$22,0)) -> 3 | G20: =INDEX('Plan Reference'!$D$5:$D$22,MATCH(E20,'Plan Reference'!$B$5:$B$22,0)) -> 12/side
A21: 1 | B21: =Settings!$B$4+(A21-1)*7+4 -> 46213 | C21: =TEXT(B21,"dddd") -> Friday | D21: Circuit C - Full Body & Core (Friday) | E21: Side Plank | F21: =INDEX('Plan Reference'!$C$5:$C$22,MATCH(E21,'Plan Reference'!$B$5:$B$22,0)) -> 3 | G21: =INDEX('Plan Reference'!$D$5:$D$22,MATCH(E21,'Plan Reference'!$B$5:$B$22,0)) -> 20-30 sec/side
A22: 1 | B22: =Settings!$B$4+(A22-1)*7+4 -> 46213 | C22: =TEXT(B22,"dddd") -> Friday | D22: Circuit C - Full Body & Core (Friday) | E22: Mountain Climbers | F22: =INDEX('Plan Reference'!$C$5:$C$22,MATCH(E22,'Plan Reference'!$B$5:$B$22,0)) -> 3 | G22: =INDEX('Plan Reference'!$D$5:$D$22,MATCH(E22,'Plan Reference'!$B$5:$B$22,0)) -> 30 sec
A23: 2 | B23: =Settings!$B$4+(A23-1)*7+0 -> 46216 | C23: =TEXT(B23,"dddd") -> Monday | D23: Circuit A - Lower Body & Core (Monday) | E23: Goblet Squat | F23: =INDEX('Plan Reference'!$C$5:$C$22,MATCH(E23,'Plan Reference'!$B$5:$B$22,0)) -> 3 | G23: =INDEX('Plan Reference'!$D$5:$D$22,MATCH(E23,'Plan Reference'!$B$5:$B$22,0)) -> 12
A24: 2 | B24: =Settings!$B$4+(A24-1)*7+0 -> 46216 | C24: =TEXT(B24,"dddd") -> Monday | D24: Circuit A - Lower Body & Core (Monday) | E24: Dumbbell Romanian Deadlift | F24: =INDEX('Plan Reference'!$C$5:$C$22,MATCH(E24,'Plan Reference'!$B$5:$B$22,0)) -> 3 | G24: =INDEX('Plan Reference'!$D$5:$D$22,MATCH(E24,'Plan Reference'!$B$5:$B$22,0)) -> 12
A25: 2 | B25: =Settings!$B$4+(A25-1)*7+0 -> 46216 | C25: =TEXT(B25,"dddd") -> Monday | D25: Circuit A - Lower Body & Core (Monday) | E25: Dumbbell Walking Lunge | F25: =INDEX('Plan Reference'!$C$5:$C$22,MATCH(E25,'Plan Reference'!$B$5:$B$22,0)) -> 3 | G25: =INDEX('Plan Reference'!$D$5:$D$22,MATCH(E25,'Plan Reference'!$B$5:$B$22,0)) -> 10/leg
A26: 2 | B26: =Settings!$B$4+(A26-1)*7+0 -> 46216 | C26: =TEXT(B26,"dddd") -> Monday | D26: Circuit A - Lower Body & Core (Monday) | E26: Glute Bridge | F26: =INDEX('Plan Reference'!$C$5:$C$22,MATCH(E26,'Plan Reference'!$B$5:$B$22,0)) -> 3 | G26: =INDEX('Plan Reference'!$D$5:$D$22,MATCH(E26,'Plan Reference'!$B$5:$B$22,0)) -> 15
A27: 2 | B27: =Settings!$B$4+(A27-1)*7+0 -> 46216 | C27: =TEXT(B27,"dddd") -> Monday | D27: Circuit A - Lower Body & Core (Monday) | E27: Plank | F27: =INDEX('Plan Reference'!$C$5:$C$22,MATCH(E27,'Plan Reference'!$B$5:$B$22,0)) -> 3 | G27: =INDEX('Plan Reference'!$D$5:$D$22,MATCH(E27,'Plan Reference'!$B$5:$B$22,0)) -> 30-45 sec
A28: 2 | B28: =Settings!$B$4+(A28-1)*7+0 -> 46216 | C28: =TEXT(B28,"dddd") -> Monday | D28: Circuit A - Lower Body & Core (Monday) | E28: Standing Calf Raise | F28: =INDEX('Plan Reference'!$C$5:$C$22,MATCH(E28,'Plan Reference'!$B$5:$B$22,0)) -> 3 | G28: =INDEX('Plan Reference'!$D$5:$D$22,MATCH(E28,'Plan Reference'!$B$5:$B$22,0)) -> 15
A29: 2 | B29: =Settings!$B$4+(A29-1)*7+2 -> 46218 | C29: =TEXT(B29,"dddd") -> Wednesday | D29: Circuit B - Upper Body & Core (Wednesday) | E29: Dumbbell Floor Press | F29: =INDEX('Plan Reference'!$C$5:$C$22,MATCH(E29,'Plan Reference'!$B$5:$B$22,0)) -> 3 | G29: =INDEX('Plan Reference'!$D$5:$D$22,MATCH(E29,'Plan Reference'!$B$5:$B$22,0)) -> 12
A30: 2 | B30: =Settings!$B$4+(A30-1)*7+2 -> 46218 | C30: =TEXT(B30,"dddd") -> Wednesday | D30: Circuit B - Upper Body & Core (Wednesday) | E30: Dumbbell Bent-Over Row | F30: =INDEX('Plan Reference'!$C$5:$C$22,MATCH(E30,'Plan Reference'!$B$5:$B$22,0)) -> 3 | G30: =INDEX('Plan Reference'!$D$5:$D$22,MATCH(E30,'Plan Reference'!$B$5:$B$22,0)) -> 12
A31: 2 | B31: =Settings!$B$4+(A31-1)*7+2 -> 46218 | C31: =TEXT(B31,"dddd") -> Wednesday | D31: Circuit B - Upper Body & Core (Wednesday) | E31: Dumbbell Shoulder Press | F31: =INDEX('Plan Reference'!$C$5:$C$22,MATCH(E31,'Plan Reference'!$B$5:$B$22,0)) -> 3 | G31: =INDEX('Plan Reference'!$D$5:$D$22,MATCH(E31,'Plan Reference'!$B$5:$B$22,0)) -> 12
A32: 2 | B32: =Settings!$B$4+(A32-1)*7+2 -> 46218 | C32: =TEXT(B32,"dddd") -> Wednesday | D32: Circuit B - Upper Body & Core (Wednesday) | E32: Band Pull-Apart | F32: =INDEX('Plan Reference'!$C$5:$C$22,MATCH(E32,'Plan Reference'!$B$5:$B$22,0)) -> 3 | G32: =INDEX('Plan Reference'!$D$5:$D$22,MATCH(E32,'Plan Reference'!$B$5:$B$22,0)) -> 15
A33: 2 | B33: =Settings!$B$4+(A33-1)*7+2 -> 46218 | C33: =TEXT(B33,"dddd") -> Wednesday | D33: Circuit B - Upper Body & Core (Wednesday) | E33: Dumbbell Bicep Curl | F33: =INDEX('Plan Reference'!$C$5:$C$22,MATCH(E33,'Plan Reference'!$B$5:$B$22,0)) -> 3 | G33: =INDEX('Plan Reference'!$D$5:$D$22,MATCH(E33,'Plan Reference'!$B$5:$B$22,0)) -> 12
A34: 2 | B34: =Settings!$B$4+(A34-1)*7+2 -> 46218 | C34: =TEXT(B34,"dddd") -> Wednesday | D34: Circuit B - Upper Body & Core (Wednesday) | E34: Dead Bug | F34: =INDEX('Plan Reference'!$C$5:$C$22,MATCH(E34,'Plan Reference'!$B$5:$B$22,0)) -> 3 | G34: =INDEX('Plan Reference'!$D$5:$D$22,MATCH(E34,'Plan Reference'!$B$5:$B$22,0)) -> 12/side
A35: 2 | B35: =Settings!$B$4+(A35-1)*7+4 -> 46220 | C35: =TEXT(B35,"dddd") -> Friday | D35: Circuit C - Full Body & Core (Friday) | E35: Dumbbell Thruster | F35: =INDEX('Plan Reference'!$C$5:$C$22,MATCH(E35,'Plan Reference'!$B$5:$B$22,0)) -> 3 | G35: =INDEX('Plan Reference'!$D$5:$D$22,MATCH(E35,'Plan Reference'!$B$5:$B$22,0)) -> 12
A36: 2 | B36: =Settings!$B$4+(A36-1)*7+4 -> 46220 | C36: =TEXT(B36,"dddd") -> Friday | D36: Circuit C - Full Body & Core (Friday) | E36: Renegade Row | F36: =INDEX('Plan Reference'!$C$5:$C$22,MATCH(E36,'Plan Reference'!$B$5:$B$22,0)) -> 3 | G36: =INDEX('Plan Reference'!$D$5:$D$22,MATCH(E36,'Plan Reference'!$B$5:$B$22,0)) -> 10/side
A37: 2 | B37: =Settings!$B$4+(A37-1)*7+4 -> 46220 | C37: =TEXT(B37,"dddd") -> Friday | D37: Circuit C - Full Body & Core (Friday) | E37: Reverse Lunge to Curl | F37: =INDEX('Plan Reference'!$C$5:$C$22,MATCH(E37,'Plan Reference'!$B$5:$B$22,0)) -> 3 | G37: =INDEX('Plan Reference'!$D$5:$D$22,MATCH(E37,'Plan Reference'!$B$5:$B$22,0)) -> 10/leg
A38: 2 | B38: =Settings!$B$4+(A38-1)*7+4 -> 46220 | C38: =TEXT(B38,"dddd") -> Friday | D38: Circuit C - Full Body & Core (Friday) | E38: Bird Dog | F38: =INDEX('Plan Reference'!$C$5:$C$22,MATCH(E38,'Plan Reference'!$B$5:$B$22,0)) -> 3 | G38: =INDEX('Plan Reference'!$D$5:$D$22,MATCH(E38,'Plan Reference'!$B$5:$B$22,0)) -> 12/side
A39: 2 | B39: =Settings!$B$4+(A39-1)*7+4 -> 46220 | C39: =TEXT(B39,"dddd") -> Friday | D39: Circuit C - Full Body & Core (Friday) | E39: Side Plank | F39: =INDEX('Plan Reference'!$C$5:$C$22,MATCH(E39,'Plan Reference'!$B$5:$B$22,0)) -> 3 | G39: =INDEX('Plan Reference'!$D$5:$D$22,MATCH(E39,'Plan Reference'!$B$5:$B$22,0)) -> 20-30 sec/side
A40: 2 | B40: =Settings!$B$4+(A40-1)*7+4 -> 46220 | C40: =TEXT(B40,"dddd") -> Friday | D40: Circuit C - Full Body & Core (Friday) | E40: Mountain Climbers | F40: =INDEX('Plan Reference'!$C$5:$C$22,MATCH(E40,'Plan Reference'!$B$5:$B$22,0)) -> 3 | G40: =INDEX('Plan Reference'!$D$5:$D$22,MATCH(E40,'Plan Reference'!$B$5:$B$22,0)) -> 30 sec
A41: 3 | B41: =Settings!$B$4+(A41-1)*7+0 -> 46223 | C41: =TEXT(B41,"dddd") -> Monday | D41: Circuit A - Lower Body & Core (Monday) | E41: Goblet Squat | F41: =INDEX('Plan Reference'!$C$5:$C$22,MATCH(E41,'Plan Reference'!$B$5:$B$22,0)) -> 3 | G41: =INDEX('Plan Reference'!$D$5:$D$22,MATCH(E41,'Plan Reference'!$B$5:$B$22,0)) -> 12
...

Sheet Weight & Waist
A1: Weight & Waist Log
A2: Measure every weekend (Sunday). Week 0 is your baseline and is linked to Settings.
A4: Week # | B4: Date | C4: Weight (lb) | D4: Waist (in) | E4: Goal Weight (lb) | F4: Goal Waist (in) | G4: Δ Weight from Start | H4: Δ Waist from Start | I4: Δ Weight from Prior Week | J4: % Progress to Goal Weight | K4: % Progress to Goal Waist | L4: Notes
A5: 0 | B5: =Settings!$B$4-1 -> 46208 | C5: =Settings!$B$5 -> 185 | D5: =Settings!$B$6 -> 35 | E5: =Settings!$B$7 -> 165 | F5: =Settings!$B$8 -> 32 | G5: =IF(C5="","",C5-Settings!$B$5) -> 0 | H5: =IF(D5="","",D5-Settings!$B$6) -> 0 | J5: =IF(C5="","",(Settings!$B$5-C5)/(Settings!$B$5-Settings!$B$7)) -> 0 | K5: =IF(D5="","",(Settings!$B$6-D5)/(Settings!$B$6-Settings!$B$8)) -> 0 | L5: Baseline
A6: 1 | B6: =Settings!$B$4+(1-1)*7+6 -> 46215 | E6: =Settings!$B$7 -> 165 | F6: =Settings!$B$8 -> 32 | G6: =IF(C6="","",C6-Settings!$B$5) | H6: =IF(D6="","",D6-Settings!$B$6) | I6: =IF(OR(C6="",C5=""),"",C6-C5) | J6: =IF(C6="","",(Settings!$B$5-C6)/(Settings!$B$5-Settings!$B$7)) | K6: =IF(D6="","",(Settings!$B$6-D6)/(Settings!$B$6-Settings!$B$8))
A7: 2 | B7: =Settings!$B$4+(2-1)*7+6 -> 46222 | E7: =Settings!$B$7 -> 165 | F7: =Settings!$B$8 -> 32 | G7: =IF(C7="","",C7-Settings!$B$5) | H7: =IF(D7="","",D7-Settings!$B$6) | I7: =IF(OR(C7="",C6=""),"",C7-C6) | J7: =IF(C7="","",(Settings!$B$5-C7)/(Settings!$B$5-Settings!$B$7)) | K7: =IF(D7="","",(Settings!$B$6-D7)/(Settings!$B$6-Settings!$B$8))
A8: 3 | B8: =Settings!$B$4+(3-1)*7+6 -> 46229 | E8: =Settings!$B$7 -> 165 | F8: =Settings!$B$8 -> 32 | G8: =IF(C8="","",C8-Settings!$B$5) | H8: =IF(D8="","",D8-Settings!$B$6) | I8: =IF(OR(C8="",C7=""),"",C8-C7) | J8: =IF(C8="","",(Settings!$B$5-C8)/(Settings!$B$5-Settings!$B$7)) | K8: =IF(D8="","",(Settings!$B$6-D8)/(Settings!$B$6-Settings!$B$8))
A9: 4 | B9: =Settings!$B$4+(4-1)*7+6 -> 46236 | E9: =Settings!$B$7 -> 165 | F9: =Settings!$B$8 -> 32 | G9: =IF(C9="","",C9-Settings!$B$5) | H9: =IF(D9="","",D9-Settings!$B$6) | I9: =IF(OR(C9="",C8=""),"",C9-C8) | J9: =IF(C9="","",(Settings!$B$5-C9)/(Settings!$B$5-Settings!$B$7)) | K9: =IF(D9="","",(Settings!$B$6-D9)/(Settings!$B$6-Settings!$B$8))
A10: 5 | B10: =Settings!$B$4+(5-1)*7+6 -> 46243 | E10: =Settings!$B$7 -> 165 | F10: =Settings!$B$8 -> 32 | G10: =IF(C10="","",C10-Settings!$B$5) | H10: =IF(D10="","",D10-Settings!$B$6) | I10: =IF(OR(C10="",C9=""),"",C10-C9) | J10: =IF(C10="","",(Settings!$B$5-C10)/(Settings!$B$5-Settings!$B$7)) | K10: =IF(D10="","",(Settings!$B$6-D10)/(Settings!$B$6-Settings!$B$8))
A11: 6 | B11: =Settings!$B$4+(6-1)*7+6 -> 46250 | E11: =Settings!$B$7 -> 165 | F11: =Settings!$B$8 -> 32 | G11: =IF(C11="","",C11-Settings!$B$5) | H11: =IF(D11="","",D11-Settings!$B$6) | I11: =IF(OR(C11="",C10=""),"",C11-C10) | J11: =IF(C11="","",(Settings!$B$5-C11)/(Settings!$B$5-Settings!$B$7)) | K11: =IF(D11="","",(Settings!$B$6-D11)/(Settings!$B$6-Settings!$B$8))
A12: 7 | B12: =Settings!$B$4+(7-1)*7+6 -> 46257 | E12: =Settings!$B$7 -> 165 | F12: =Settings!$B$8 -> 32 | G12: =IF(C12="","",C12-Settings!$B$5) | H12: =IF(D12="","",D12-Settings!$B$6) | I12: =IF(OR(C12="",C11=""),"",C12-C11) | J12: =IF(C12="","",(Settings!$B$5-C12)/(Settings!$B$5-Settings!$B$7)) | K12: =IF(D12="","",(Settings!$B$6-D12)/(Settings!$B$6-Settings!$B$8))
A13: 8 | B13: =Settings!$B$4+(8-1)*7+6 -> 46264 | E13: =Settings!$B$7 -> 165 | F13: =Settings!$B$8 -> 32 | G13: =IF(C13="","",C13-Settings!$B$5) | H13: =IF(D13="","",D13-Settings!$B$6) | I13: =IF(OR(C13="",C12=""),"",C13-C12) | J13: =IF(C13="","",(Settings!$B$5-C13)/(Settings!$B$5-Settings!$B$7)) | K13: =IF(D13="","",(Settings!$B$6-D13)/(Settings!$B$6-Settings!$B$8))
A14: 9 | B14: =Settings!$B$4+(9-1)*7+6 -> 46271 | E14: =Settings!$B$7 -> 165 | F14: =Settings!$B$8 -> 32 | G14: =IF(C14="","",C14-Settings!$B$5) | H14: =IF(D14="","",D14-Settings!$B$6) | I14: =IF(OR(C14="",C13=""),"",C14-C13) | J14: =IF(C14="","",(Settings!$B$5-C14)/(Settings!$B$5-Settings!$B$7)) | K14: =IF(D14="","",(Settings!$B$6-D14)/(Settings!$B$6-Settings!$B$8))
A15: 10 | B15: =Settings!$B$4+(10-1)*7+6 -> 46278 | E15: =Settings!$B$7 -> 165 | F15: =Settings!$B$8 -> 32 | G15: =IF(C15="","",C15-Settings!$B$5) | H15: =IF(D15="","",D15-Settings!$B$6) | I15: =IF(OR(C15="",C14=""),"",C15-C14) | J15: =IF(C15="","",(Settings!$B$5-C15)/(Settings!$B$5-Settings!$B$7)) | K15: =IF(D15="","",(Settings!$B$6-D15)/(Settings!$B$6-Settings!$B$8))
A16: 11 | B16: =Settings!$B$4+(11-1)*7+6 -> 46285 | E16: =Settings!$B$7 -> 165 | F16: =Settings!$B$8 -> 32 | G16: =IF(C16="","",C16-Settings!$B$5) | H16: =IF(D16="","",D16-Settings!$B$6) | I16: =IF(OR(C16="",C15=""),"",C16-C15) | J16: =IF(C16="","",(Settings!$B$5-C16)/(Settings!$B$5-Settings!$B$7)) | K16: =IF(D16="","",(Settings!$B$6-D16)/(Settings!$B$6-Settings!$B$8))
A17: 12 | B17: =Settings!$B$4+(12-1)*7+6 -> 46292 | E17: =Settings!$B$7 -> 165 | F17: =Settings!$B$8 -> 32 | G17: =IF(C17="","",C17-Settings!$B$5) | H17: =IF(D17="","",D17-Settings!$B$6) | I17: =IF(OR(C17="",C16=""),"",C17-C16) | J17: =IF(C17="","",(Settings!$B$5-C17)/(Settings!$B$5-Settings!$B$7)) | K17: =IF(D17="","",(Settings!$B$6-D17)/(Settings!$B$6-Settings!$B$8))

Sheet Trends
A1: Weekly Trend Aggregates
A2: Calculated automatically from Daily Log and Strength Log. Feeds the Dashboard charts.
A4: Week # | B4: Weekly Jog Mileage (mi) | C4: Target Weekly Mileage (mi) | D4: Strength Sessions Completed | E4: Target Sessions/Week | F4: Goblet Squat - Max Weight (lb) | G4: Dumbbell Floor Press - Max Weight (lb) | H4: Dumbbell Thruster - Max Weight (lb)
A5: 1 | B5: =SUMIFS('Daily Log'!$E$5:$E$88,'Daily Log'!$A$5:$A$88,A5) -> 0 | C5: =Settings!$B$9/4.33 -> 13.856813 | D5: =ROUND(COUNTIFS('Strength Log'!$A$5:$A$220,A5,'Strength Log'!$H$5:$H$220,"<>")/6,1) -> 0 | E5: =Settings!$B$10 -> 3 | F5: =IFERROR(maxifs('Strength Log'!$J$5:$J$220,'Strength Log'!$A$5:$A$220,A5,'Strength Log'!$E$5:$E$220,"Goblet Squat"),"") | G5: =IFERROR(maxifs('Strength Log'!$J$5:$J$220,'Strength Log'!$A$5:$A$220,A5,'Strength Log'!$E$5:$E$220,"Dumbbell Floor Press"),"") | H5: =IFERROR(maxifs('Strength Log'!$J$5:$J$220,'Strength Log'!$A$5:$A$220,A5,'Strength Log'!$E$5:$E$220,"Dumbbell Thruster"),"")
A6: 2 | B6: =SUMIFS('Daily Log'!$E$5:$E$88,'Daily Log'!$A$5:$A$88,A6) -> 0 | C6: =Settings!$B$9/4.33 -> 13.856813 | D6: =ROUND(COUNTIFS('Strength Log'!$A$5:$A$220,A6,'Strength Log'!$H$5:$H$220,"<>")/6,1) -> 0 | E6: =Settings!$B$10 -> 3 | F6: =IFERROR(maxifs('Strength Log'!$J$5:$J$220,'Strength Log'!$A$5:$A$220,A6,'Strength Log'!$E$5:$E$220,"Goblet Squat"),"") | G6: =IFERROR(maxifs('Strength Log'!$J$5:$J$220,'Strength Log'!$A$5:$A$220,A6,'Strength Log'!$E$5:$E$220,"Dumbbell Floor Press"),"") | H6: =IFERROR(maxifs('Strength Log'!$J$5:$J$220,'Strength Log'!$A$5:$A$220,A6,'Strength Log'!$E$5:$E$220,"Dumbbell Thruster"),"")
A7: 3 | B7: =SUMIFS('Daily Log'!$E$5:$E$88,'Daily Log'!$A$5:$A$88,A7) -> 0 | C7: =Settings!$B$9/4.33 -> 13.856813 | D7: =ROUND(COUNTIFS('Strength Log'!$A$5:$A$220,A7,'Strength Log'!$H$5:$H$220,"<>")/6,1) -> 0 | E7: =Settings!$B$10 -> 3 | F7: =IFERROR(maxifs('Strength Log'!$J$5:$J$220,'Strength Log'!$A$5:$A$220,A7,'Strength Log'!$E$5:$E$220,"Goblet Squat"),"") | G7: =IFERROR(maxifs('Strength Log'!$J$5:$J$220,'Strength Log'!$A$5:$A$220,A7,'Strength Log'!$E$5:$E$220,"Dumbbell Floor Press"),"") | H7: =IFERROR(maxifs('Strength Log'!$J$5:$J$220,'Strength Log'!$A$5:$A$220,A7,'Strength Log'!$E$5:$E$220,"Dumbbell Thruster"),"")
A8: 4 | B8: =SUMIFS('Daily Log'!$E$5:$E$88,'Daily Log'!$A$5:$A$88,A8) -> 0 | C8: =Settings!$B$9/4.33 -> 13.856813 | D8: =ROUND(COUNTIFS('Strength Log'!$A$5:$A$220,A8,'Strength Log'!$H$5:$H$220,"<>")/6,1) -> 0 | E8: =Settings!$B$10 -> 3 | F8: =IFERROR(maxifs('Strength Log'!$J$5:$J$220,'Strength Log'!$A$5:$A$220,A8,'Strength Log'!$E$5:$E$220,"Goblet Squat"),"") | G8: =IFERROR(maxifs('Strength Log'!$J$5:$J$220,'Strength Log'!$A$5:$A$220,A8,'Strength Log'!$E$5:$E$220,"Dumbbell Floor Press"),"") | H8: =IFERROR(maxifs('Strength Log'!$J$5:$J$220,'Strength Log'!$A$5:$A$220,A8,'Strength Log'!$E$5:$E$220,"Dumbbell Thruster"),"")
A9: 5 | B9: =SUMIFS('Daily Log'!$E$5:$E$88,'Daily Log'!$A$5:$A$88,A9) -> 0 | C9: =Settings!$B$9/4.33 -> 13.856813 | D9: =ROUND(COUNTIFS('Strength Log'!$A$5:$A$220,A9,'Strength Log'!$H$5:$H$220,"<>")/6,1) -> 0 | E9: =Settings!$B$10 -> 3 | F9: =IFERROR(maxifs('Strength Log'!$J$5:$J$220,'Strength Log'!$A$5:$A$220,A9,'Strength Log'!$E$5:$E$220,"Goblet Squat"),"") | G9: =IFERROR(maxifs('Strength Log'!$J$5:$J$220,'Strength Log'!$A$5:$A$220,A9,'Strength Log'!$E$5:$E$220,"Dumbbell Floor Press"),"") | H9: =IFERROR(maxifs('Strength Log'!$J$5:$J$220,'Strength Log'!$A$5:$A$220,A9,'Strength Log'!$E$5:$E$220,"Dumbbell Thruster"),"")
A10: 6 | B10: =SUMIFS('Daily Log'!$E$5:$E$88,'Daily Log'!$A$5:$A$88,A10) -> 0 | C10: =Settings!$B$9/4.33 -> 13.856813 | D10: =ROUND(COUNTIFS('Strength Log'!$A$5:$A$220,A10,'Strength Log'!$H$5:$H$220,"<>")/6,1) -> 0 | E10: =Settings!$B$10 -> 3 | F10: =IFERROR(maxifs('Strength Log'!$J$5:$J$220,'Strength Log'!$A$5:$A$220,A10,'Strength Log'!$E$5:$E$220,"Goblet Squat"),"") | G10: =IFERROR(maxifs('Strength Log'!$J$5:$J$220,'Strength Log'!$A$5:$A$220,A10,'Strength Log'!$E$5:$E$220,"Dumbbell Floor Press"),"") | H10: =IFERROR(maxifs('Strength Log'!$J$5:$J$220,'Strength Log'!$A$5:$A$220,A10,'Strength Log'!$E$5:$E$220,"Dumbbell Thruster"),"")
A11: 7 | B11: =SUMIFS('Daily Log'!$E$5:$E$88,'Daily Log'!$A$5:$A$88,A11) -> 0 | C11: =Settings!$B$9/4.33 -> 13.856813 | D11: =ROUND(COUNTIFS('Strength Log'!$A$5:$A$220,A11,'Strength Log'!$H$5:$H$220,"<>")/6,1) -> 0 | E11: =Settings!$B$10 -> 3 | F11: =IFERROR(maxifs('Strength Log'!$J$5:$J$220,'Strength Log'!$A$5:$A$220,A11,'Strength Log'!$E$5:$E$220,"Goblet Squat"),"") | G11: =IFERROR(maxifs('Strength Log'!$J$5:$J$220,'Strength Log'!$A$5:$A$220,A11,'Strength Log'!$E$5:$E$220,"Dumbbell Floor Press"),"") | H11: =IFERROR(maxifs('Strength Log'!$J$5:$J$220,'Strength Log'!$A$5:$A$220,A11,'Strength Log'!$E$5:$E$220,"Dumbbell Thruster"),"")
A12: 8 | B12: =SUMIFS('Daily Log'!$E$5:$E$88,'Daily Log'!$A$5:$A$88,A12) -> 0 | C12: =Settings!$B$9/4.33 -> 13.856813 | D12: =ROUND(COUNTIFS('Strength Log'!$A$5:$A$220,A12,'Strength Log'!$H$5:$H$220,"<>")/6,1) -> 0 | E12: =Settings!$B$10 -> 3 | F12: =IFERROR(maxifs('Strength Log'!$J$5:$J$220,'Strength Log'!$A$5:$A$220,A12,'Strength Log'!$E$5:$E$220,"Goblet Squat"),"") | G12: =IFERROR(maxifs('Strength Log'!$J$5:$J$220,'Strength Log'!$A$5:$A$220,A12,'Strength Log'!$E$5:$E$220,"Dumbbell Floor Press"),"") | H12: =IFERROR(maxifs('Strength Log'!$J$5:$J$220,'Strength Log'!$A$5:$A$220,A12,'Strength Log'!$E$5:$E$220,"Dumbbell Thruster"),"")
A13: 9 | B13: =SUMIFS('Daily Log'!$E$5:$E$88,'Daily Log'!$A$5:$A$88,A13) -> 0 | C13: =Settings!$B$9/4.33 -> 13.856813 | D13: =ROUND(COUNTIFS('Strength Log'!$A$5:$A$220,A13,'Strength Log'!$H$5:$H$220,"<>")/6,1) -> 0 | E13: =Settings!$B$10 -> 3 | F13: =IFERROR(maxifs('Strength Log'!$J$5:$J$220,'Strength Log'!$A$5:$A$220,A13,'Strength Log'!$E$5:$E$220,"Goblet Squat"),"") | G13: =IFERROR(maxifs('Strength Log'!$J$5:$J$220,'Strength Log'!$A$5:$A$220,A13,'Strength Log'!$E$5:$E$220,"Dumbbell Floor Press"),"") | H13: =IFERROR(maxifs('Strength Log'!$J$5:$J$220,'Strength Log'!$A$5:$A$220,A13,'Strength Log'!$E$5:$E$220,"Dumbbell Thruster"),"")
A14: 10 | B14: =SUMIFS('Daily Log'!$E$5:$E$88,'Daily Log'!$A$5:$A$88,A14) -> 0 | C14: =Settings!$B$9/4.33 -> 13.856813 | D14: =ROUND(COUNTIFS('Strength Log'!$A$5:$A$220,A14,'Strength Log'!$H$5:$H$220,"<>")/6,1) -> 0 | E14: =Settings!$B$10 -> 3 | F14: =IFERROR(maxifs('Strength Log'!$J$5:$J$220,'Strength Log'!$A$5:$A$220,A14,'Strength Log'!$E$5:$E$220,"Goblet Squat"),"") | G14: =IFERROR(maxifs('Strength Log'!$J$5:$J$220,'Strength Log'!$A$5:$A$220,A14,'Strength Log'!$E$5:$E$220,"Dumbbell Floor Press"),"") | H14: =IFERROR(maxifs('Strength Log'!$J$5:$J$220,'Strength Log'!$A$5:$A$220,A14,'Strength Log'!$E$5:$E$220,"Dumbbell Thruster"),"")
A15: 11 | B15: =SUMIFS('Daily Log'!$E$5:$E$88,'Daily Log'!$A$5:$A$88,A15) -> 0 | C15: =Settings!$B$9/4.33 -> 13.856813 | D15: =ROUND(COUNTIFS('Strength Log'!$A$5:$A$220,A15,'Strength Log'!$H$5:$H$220,"<>")/6,1) -> 0 | E15: =Settings!$B$10 -> 3 | F15: =IFERROR(maxifs('Strength Log'!$J$5:$J$220,'Strength Log'!$A$5:$A$220,A15,'Strength Log'!$E$5:$E$220,"Goblet Squat"),"") | G15: =IFERROR(maxifs('Strength Log'!$J$5:$J$220,'Strength Log'!$A$5:$A$220,A15,'Strength Log'!$E$5:$E$220,"Dumbbell Floor Press"),"") | H15: =IFERROR(maxifs('Strength Log'!$J$5:$J$220,'Strength Log'!$A$5:$A$220,A15,'Strength Log'!$E$5:$E$220,"Dumbbell Thruster"),"")
A16: 12 | B16: =SUMIFS('Daily Log'!$E$5:$E$88,'Daily Log'!$A$5:$A$88,A16) -> 0 | C16: =Settings!$B$9/4.33 -> 13.856813 | D16: =ROUND(COUNTIFS('Strength Log'!$A$5:$A$220,A16,'Strength Log'!$H$5:$H$220,"<>")/6,1) -> 0 | E16: =Settings!$B$10 -> 3 | F16: =IFERROR(maxifs('Strength Log'!$J$5:$J$220,'Strength Log'!$A$5:$A$220,A16,'Strength Log'!$E$5:$E$220,"Goblet Squat"),"") | G16: =IFERROR(maxifs('Strength Log'!$J$5:$J$220,'Strength Log'!$A$5:$A$220,A16,'Strength Log'!$E$5:$E$220,"Dumbbell Floor Press"),"") | H16: =IFERROR(maxifs('Strength Log'!$J$5:$J$220,'Strength Log'!$A$5:$A$220,A16,'Strength Log'!$E$5:$E$220,"Dumbbell Thruster"),"")

Sheet Dashboard
A1: Amit's Progress Dashboard
A2: All charts update automatically as you log data in Strength Log, Daily Log, and Weight & Waist.
